10:38:59 PM:ERROR [conexion.py:25] Ocurrió un error: connection to server at "127.0.0.1", port 5432 failed: Connection refused (0x0000274D/10061)
	Is the server running on that host and accepting TCP/IP connections?

10:48:13 PM:ERROR [conexion.py:25] Ocurrió un error: connection to server at "127.0.0.1", port 5432 failed: FATAL:  password authentication failed for user "postgres"

